<mujoco>
    <option gravity="0 0 0" timestep="0.01"/>
<default>
<geom rgba="0 0 0 1"/>
</default>
    <worldbody>
 	<light diffuse=".2 .2 .2" pos="0 0 20" dir="0 0 -1" mode="track"/> 
	<body>
	  <geom name='floor' pos='0 0 -0.4' size='5 5 .1' mass="10000" type='box' condim='3' rgba=".9 .9 .9 1"/>    
	</body>
	<body>
	  <geom name='wall1' pos='-5.1 0 -0.2' size='.1 5.1 .5' mass="10000" type='box' condim='3'/> 
	</body>
	<body>   
	  <geom name='wall2' pos='5.1 0 -0.2' size='.1 5.1 .5' mass="10000" type='box' condim='3'/>   
	</body>
	<body> 
	  <geom name='wall3' pos='0 -5 -0.2' size='5 .1 .5' mass="10000" type='box' condim='3'/>  
	</body>
	<body>  
	  <geom name='wall4' pos='0 5 -0.2' size='5 .1 .5' mass="10000" type='box' condim='3'/>   
	</body>
        <body name="predator" pos="3.5 3.5 0">           
            <joint axis="1 0 0" damping="0" name="predator0" pos="0 0 0" type="slide"/>
            <joint axis="0 1 0" damping="0" name="predator1" pos="0 0 0" type="slide"/>
      <!--      <joint axis="0 0 1" damping="0" name="predator2" pos="0 0 0" type="slide"/> -->
            <geom type="sphere" size="0.2" mass="10" rgba="1 0 0 1"/>
    	    <site name="end1" pos="0 0 0" type="sphere" size="0.01"/>
        </body>
 	<body name="prey" pos="0 0 0">
            <joint axis="1 0 0" damping="0" name="prey0" pos="0 0 0" type="slide"/>
            <joint axis="0 1 0" damping="0" name="prey1" pos="0 0 0" type="slide"/>
      <!--      <joint axis="0 0 1" damping="0" name="prey2" pos="0 0 0" type="slide"/> -->
            <geom type="sphere" size="0.2" mass="8" rgba="0 1 0 1"/>
        </body>

	<body name="dragger" pos="4.5 4.5 0">
            <joint axis="1 0 0" damping="0" name="dragger0" pos="0 0 0" type="slide"/>
            <joint axis="0 1 0" damping="0" name="dragger1" pos="0 0 0" type="slide"/>
      <!--      <joint axis="0 0 1" damping="0" name="dragger2" pos="0 0 0" type="slide"/> -->
            <geom type="sphere" size="0.2" mass="75" rgba="0 0 1 1"/>
 	    <site name="end2" pos="0 0 0" type="sphere" size="0.01"/>	
        </body>	

      <!--<body pos="4.3 4.3 0">
		<joint type="free"/>
		<geom type="sphere" size="0.01" rgba="0 .9 0 1"/>
  		<site name="middle4" pos="0 0 0" type="sphere" size="0.01"/>
	</body>
	<body pos="4.1 4.1 0">
		<joint type="free"/>
		<geom type="sphere" size="0.01" rgba="0 .9 0 1"/>
  		<site name="middle3" pos="0 0 0" type="sphere" size="0.01"/>
	</body>
	<body pos="3.9 3.9 0">
		<joint type="free"/>
		<geom type="sphere" size="0.01" rgba="0 .9 0 1"/>
  		<site name="middle2" pos="0 0 0" type="sphere" size="0.01"/>
	</body>
	<body pos="3.7 3.7 0">
		<joint type="free"/>
		<geom type="sphere" size="0.01" rgba="0 .9 0 1"/>
  		<site name="middle1" pos="0 0 0" type="sphere" size="0.01"/>
	</body> -->
    </worldbody>

     <!-- <tendon>
        <spatial limited="true" range="0 .75" stiffness="10" damping=".6" width="0.01">
            <site site="end1"/>
            <site site="middle1"/>
        </spatial>
    </tendon>
    <tendon>
        <spatial limited="true" range="0 .75" stiffness="10" damping=".6" width="0.01">
            <site site="middle1"/>
            <site site="middle2"/>
        </spatial>
    </tendon>
    <tendon>
        <spatial limited="true" range="0 .75" stiffness="10" damping=".6" width="0.01">
            <site site="middle2"/>
            <site site="middle3"/>
        </spatial>
    </tendon>
    <tendon>
        <spatial limited="true" range="0 .75" stiffness="10" damping=".6" width="0.01">
            <site site="middle3"/>
            <site site="middle4"/>
        </spatial>
    </tendon>
    <tendon>
        <spatial limited="true" range="0 .75" stiffness="10" damping=".6" width="0.01">
            <site site="middle4"/>
            <site site="end2"/>
        </spatial>
    </tendon>-->

    <tendon>
        <spatial limited="true" range="0.75 2.5" stiffness="10" damping=".6" width="0.01">
            <site site="end1"/>
            <site site="end2"/>
        </spatial>
 	<spatial limited="true" range="0.75 2.5" stiffness="10" damping=".6" width="0.01">
            <site site="end1"/>
            <site site="end2"/>
        </spatial>
    </tendon>


    <actuator>
        <motor gear="1" joint="predator0"/>
        <motor gear="1" joint="predator1"/>

        <motor gear="1" joint="prey0"/>
        <motor gear="1" joint="prey1"/>

        <motor gear="1" joint="dragger0"/>
        <motor gear="1" joint="dragger1"/>
    </actuator>
</mujoco>.
